Workbook
Name LanguageID: 'Data'!$G$2
Name TranslationHeaders: 'Translation'!$F$1:$G$31

Sheet DRE Acumulado
A1: =Translation!$A$22 -> DRE YAMAHA BMI - Acumulado
A2: =Translation!$A$20&Data!D1 -> Concessionário: %%=$RecordSet.#4 | C2: =Translation!$A$19&Data!D3 -> Localização: %%=$RecordSet.#8 | H2: =Translation!$A$21 -> Período: | I2: =VLOOKUP(Data!D6,Data!H1:I12,2,FALSE)&" "&Data!E6 -> #N/A
A3: =Translation!A1 -> VENDA DE NOVOS | O3: VENDA NOVOS
A4: =Translation!A35 -> LINHA SCOOTER <200 cc | B4: =Translation!$G$32 -> CONTA | C4: =Translation!$G$12 -> UNIDADES | D4: =Translation!$G$11 -> RECEITA (SEM IMPOSTOS) | E4: =Translation!$G$33 -> UNIDADES DEVOLVIDAS | F4: =Translation!$G$14 -> DEVOLUÇÃO DE VENDAS | G4: =Translation!$G$3 -> ABAT. E DESCONTO | H4: =Translation!$G$9 -> RECEITA LÍQUIDA | I4: =Translation!$G$2 -> CUSTO | J4: =Translation!$G$5 -> LUCRO BRUTO | O4: LINHA SCOOTER <200 cc | P4: =Translation!$G$32 -> CONTA | Q4: UNITS | R4: SALES | S4: URETURN | T4: SC | U4: DISC | V4: NS | W4: COS | X4: GP
A5: =Translation!A36 -> NEO 125 | B5: A1000 | C5: =VLOOKUP(Q5,Data!$B:$E,4,FALSE) -> #N/A | D5: =VLOOKUP(R5,Data!$B:$E,4,FALSE) -> #N/A | E5: =VLOOKUP(S5,Data!$B:$E,4,FALSE) -> #N/A | F5: =VLOOKUP(T5,Data!$B:$E,4,FALSE) -> #N/A | G5: =VLOOKUP(U5,Data!$B:$E,4,FALSE) -> #N/A | H5: =VLOOKUP(V5,Data!$B:$E,4,FALSE) -> #N/A | I5: =VLOOKUP(W5,Data!$B:$E,4,FALSE) -> #N/A | J5: =VLOOKUP(X5,Data!$B:$E,4,FALSE) -> #N/A | O5: NEO 125 | P5: A1000 | Q5: A1000.1 | R5: A1000.2 | S5: A1000.8 | T5: A1000.3 | U5: A1000.4 | V5: A1000.5 | W5: A1000.6 | X5: A1000.7
A6: =Translation!A37 -> NMAX 160 ABS | B6: A1010 | C6: =VLOOKUP(Q6,Data!$B:$E,4,FALSE) -> #N/A | D6: =VLOOKUP(R6,Data!$B:$E,4,FALSE) -> #N/A | E6: =VLOOKUP(S6,Data!$B:$E,4,FALSE) -> #N/A | F6: =VLOOKUP(T6,Data!$B:$E,4,FALSE) -> #N/A | G6: =VLOOKUP(U6,Data!$B:$E,4,FALSE) -> #N/A | H6: =VLOOKUP(V6,Data!$B:$E,4,FALSE) -> #N/A | I6: =VLOOKUP(W6,Data!$B:$E,4,FALSE) -> #N/A | J6: =VLOOKUP(X6,Data!$B:$E,4,FALSE) -> #N/A | O6: NMAX 160 ABS | P6: A1010 | Q6: A1010.1 | R6: A1010.2 | S6: A1010.8 | T6: A1010.3 | U6: A1010.4 | V6: A1010.5 | W6: A1010.6 | X6: A1010.7
A7: =Translation!A38 -> LINHA SCOOTER >200 cc | B7: =Translation!$G$32 -> CONTA | C7: =Translation!$G$12 -> UNIDADES | D7: =Translation!$G$11 -> RECEITA (SEM IMPOSTOS) | E7: =Translation!$G$33 -> UNIDADES DEVOLVIDAS | F7: =Translation!$G$14 -> DEVOLUÇÃO DE VENDAS | G7: =Translation!$G$3 -> ABAT. E DESCONTO | H7: =Translation!$G$9 -> RECEITA LÍQUIDA | I7: =Translation!$G$2 -> CUSTO | J7: =Translation!$G$5 -> LUCRO BRUTO | O7: LINHA SCOOTER >200 cc | P7: =Translation!$G$32 -> CONTA | Q7: UNITS | R7: SALES | S7: URETURN | T7: SC | U7: DISC | V7: NS | W7: COS | X7: GP
A8: =Translation!A39 -> TMAX 530 | B8: A1020 | C8: =VLOOKUP(Q8,Data!$B:$E,4,FALSE) -> #N/A | D8: =VLOOKUP(R8,Data!$B:$E,4,FALSE) -> #N/A | E8: =VLOOKUP(S8,Data!$B:$E,4,FALSE) -> #N/A | F8: =VLOOKUP(T8,Data!$B:$E,4,FALSE) -> #N/A | G8: =VLOOKUP(U8,Data!$B:$E,4,FALSE) -> #N/A | H8: =VLOOKUP(V8,Data!$B:$E,4,FALSE) -> #N/A | I8: =VLOOKUP(W8,Data!$B:$E,4,FALSE) -> #N/A | J8: =VLOOKUP(X8,Data!$B:$E,4,FALSE) -> #N/A | O8: TMAX 530 | P8: A1020 | Q8: A1020.1 | R8: A1020.2 | S8: A1020.8 | T8: A1020.3 | U8: A1020.4 | V8: A1020.5 | W8: A1020.6 | X8: A1020.7
A9: X MAX ABS | B9: A1021 | C9: =VLOOKUP(Q9,Data!$B:$E,4,FALSE) -> #N/A | D9: =VLOOKUP(R9,Data!$B:$E,4,FALSE) -> #N/A | E9: =VLOOKUP(S9,Data!$B:$E,4,FALSE) -> #N/A | F9: =VLOOKUP(T9,Data!$B:$E,4,FALSE) -> #N/A | G9: =VLOOKUP(U9,Data!$B:$E,4,FALSE) -> #N/A | H9: =VLOOKUP(V9,Data!$B:$E,4,FALSE) -> #N/A | I9: =VLOOKUP(W9,Data!$B:$E,4,FALSE) -> #N/A | J9: =VLOOKUP(X9,Data!$B:$E,4,FALSE) -> #N/A | O9: X MAX ABS | P9: A1021 | Q9: A1021.1 | R9: A1021.2 | S9: A1021.8 | T9: A1021.3 | U9: A1021.4 | V9: A1021.5 | W9: A1021.6 | X9: A1021.7
A10: NEOS CONNECTED | B10: A1022 | C10: =VLOOKUP(Q10,Data!$B:$E,4,FALSE) -> #N/A | D10: =VLOOKUP(R10,Data!$B:$E,4,FALSE) -> #N/A | E10: =VLOOKUP(S10,Data!$B:$E,4,FALSE) -> #N/A | F10: =VLOOKUP(T10,Data!$B:$E,4,FALSE) -> #N/A | G10: =VLOOKUP(U10,Data!$B:$E,4,FALSE) -> #N/A | H10: =VLOOKUP(V10,Data!$B:$E,4,FALSE) -> #N/A | I10: =VLOOKUP(W10,Data!$B:$E,4,FALSE) -> #N/A | J10: =VLOOKUP(X10,Data!$B:$E,4,FALSE) -> #N/A | O10: NEOS CONNECTED | P10: A1022 | Q10: A1022.1 | R10: A1022.2 | S10: A1022.8 | T10: A1022.3 | U10: A1022.4 | V10: A1022.5 | W10: A1022.6 | X10: A1022.7
A11: =Translation!A40 -> TOTAL DE VENDAS - SCOOTER | B11: A1030 | C11: =VLOOKUP(Q11,Data!$B:$E,4,FALSE) -> #N/A | D11: =VLOOKUP(R11,Data!$B:$E,4,FALSE) -> #N/A | E11: =VLOOKUP(S11,Data!$B:$E,4,FALSE) -> #N/A | F11: =VLOOKUP(T11,Data!$B:$E,4,FALSE) -> #N/A | G11: =VLOOKUP(U11,Data!$B:$E,4,FALSE) -> #N/A | H11: =VLOOKUP(V11,Data!$B:$E,4,FALSE) -> #N/A | I11: =VLOOKUP(W11,Data!$B:$E,4,FALSE) -> #N/A | J11: =VLOOKUP(X11,Data!$B:$E,4,FALSE) -> #N/A | O11: TOTAL DE VENDAS - SCOOTER | P11: A1030 | Q11: A1030.1 | R11: A1030.2 | S11: A1030.8 | T11: A1030.3 | U11: A1030.4 | V11: A1030.5 | W11: A1030.6 | X11: A1030.7
A12: =Translation!A41 -> LINHA OFF ROAD | B12: =Translation!$G$32 -> CONTA | C12: =Translation!$G$12 -> UNIDADES | D12: =Translation!$G$11 -> RECEITA (SEM IMPOSTOS) | E12: =Translation!$G$33 -> UNIDADES DEVOLVIDAS | F12: =Translation!$G$14 -> DEVOLUÇÃO DE VENDAS | G12: =Translation!$G$3 -> ABAT. E DESCONTO | H12: =Translation!$G$9 -> RECEITA LÍQUIDA | I12: =Translation!$G$2 -> CUSTO | J12: =Translation!$G$5 -> LUCRO BRUTO | O12: LINHA OFF ROAD | P12: =Translation!$G$32 -> CONTA | Q12: UNITS | R12: SALES | S12: URETURN | T12: SC | U12: DISC | V12: NS | W12: COS | X12: GP
A13: =Translation!A42 -> TTR 230 | B13: A1040 | C13: =VLOOKUP(Q13,Data!$B:$E,4,FALSE) -> #N/A | D13: =VLOOKUP(R13,Data!$B:$E,4,FALSE) -> #N/A | E13: =VLOOKUP(S13,Data!$B:$E,4,FALSE) -> #N/A | F13: =VLOOKUP(T13,Data!$B:$E,4,FALSE) -> #N/A | G13: =VLOOKUP(U13,Data!$B:$E,4,FALSE) -> #N/A | H13: =VLOOKUP(V13,Data!$B:$E,4,FALSE) -> #N/A | I13: =VLOOKUP(W13,Data!$B:$E,4,FALSE) -> #N/A | J13: =VLOOKUP(X13,Data!$B:$E,4,FALSE) -> #N/A | O13: TTR 230 | P13: A1040 | Q13: A1040.1 | R13: A1040.2 | S13: A1040.8 | T13: A1040.3 | U13: A1040.4 | V13: A1040.5 | W13: A1040.6 | X13: A1040.7
A14: YZ 85LW | B14: A1045 | C14: =VLOOKUP(Q14,Data!$B:$E,4,FALSE) -> #N/A | D14: =VLOOKUP(R14,Data!$B:$E,4,FALSE) -> #N/A | E14: =VLOOKUP(S14,Data!$B:$E,4,FALSE) -> #N/A | F14: =VLOOKUP(T14,Data!$B:$E,4,FALSE) -> #N/A | G14: =VLOOKUP(U14,Data!$B:$E,4,FALSE) -> #N/A | H14: =VLOOKUP(V14,Data!$B:$E,4,FALSE) -> #N/A | I14: =VLOOKUP(W14,Data!$B:$E,4,FALSE) -> #N/A | J14: =VLOOKUP(X14,Data!$B:$E,4,FALSE) -> #N/A | O14: YZ 85LW | P14: A1045 | Q14: A1045.1 | R14: A1045.2 | S14: A1045.8 | T14: A1045.3 | U14: A1045.4 | V14: A1045.5 | W14: A1045.6 | X14: A1045.7
A15: =Translation!A44 -> YZ 250 | B15: A1050 | C15: =VLOOKUP(Q15,Data!$B:$E,4,FALSE) -> #N/A | D15: =VLOOKUP(R15,Data!$B:$E,4,FALSE) -> #N/A | E15: =VLOOKUP(S15,Data!$B:$E,4,FALSE) -> #N/A | F15: =VLOOKUP(T15,Data!$B:$E,4,FALSE) -> #N/A | G15: =VLOOKUP(U15,Data!$B:$E,4,FALSE) -> #N/A | H15: =VLOOKUP(V15,Data!$B:$E,4,FALSE) -> #N/A | I15: =VLOOKUP(W15,Data!$B:$E,4,FALSE) -> #N/A | J15: =VLOOKUP(X15,Data!$B:$E,4,FALSE) -> #N/A | O15: YZ 250 | P15: A1050 | Q15: A1050.1 | R15: A1050.2 | S15: A1050.8 | T15: A1050.3 | U15: A1050.4 | V15: A1050.5 | W15: A1050.6 | X15: A1050.7
A16: =Translation!A45 -> YZ 250F | B16: A1060 | C16: =VLOOKUP(Q16,Data!$B:$E,4,FALSE) -> #N/A | D16: =VLOOKUP(R16,Data!$B:$E,4,FALSE) -> #N/A | E16: =VLOOKUP(S16,Data!$B:$E,4,FALSE) -> #N/A | F16: =VLOOKUP(T16,Data!$B:$E,4,FALSE) -> #N/A | G16: =VLOOKUP(U16,Data!$B:$E,4,FALSE) -> #N/A | H16: =VLOOKUP(V16,Data!$B:$E,4,FALSE) -> #N/A | I16: =VLOOKUP(W16,Data!$B:$E,4,FALSE) -> #N/A | J16: =VLOOKUP(X16,Data!$B:$E,4,FALSE) -> #N/A | O16: YZ 250F | P16: A1060 | Q16: A1060.1 | R16: A1060.2 | S16: A1060.8 | T16: A1060.3 | U16: A1060.4 | V16: A1060.5 | W16: A1060.6 | X16: A1060.7
A17: =Translation!A46 -> YZ 250FX | B17: A1070 | C17: =VLOOKUP(Q17,Data!$B:$E,4,FALSE) -> #N/A | D17: =VLOOKUP(R17,Data!$B:$E,4,FALSE) -> #N/A | E17: =VLOOKUP(S17,Data!$B:$E,4,FALSE) -> #N/A | F17: =VLOOKUP(T17,Data!$B:$E,4,FALSE) -> #N/A | G17: =VLOOKUP(U17,Data!$B:$E,4,FALSE) -> #N/A | H17: =VLOOKUP(V17,Data!$B:$E,4,FALSE) -> #N/A | I17: =VLOOKUP(W17,Data!$B:$E,4,FALSE) -> #N/A | J17: =VLOOKUP(X17,Data!$B:$E,4,FALSE) -> #N/A | O17: YZ 250FX | P17: A1070 | Q17: A1070.1 | R17: A1070.2 | S17: A1070.8 | T17: A1070.3 | U17: A1070.4 | V17: A1070.5 | W17: A1070.6 | X17: A1070.7
A18: YZ 250X | B18: A1075 | C18: =VLOOKUP(Q18,Data!$B:$E,4,FALSE) -> #N/A | D18: =VLOOKUP(R18,Data!$B:$E,4,FALSE) -> #N/A | E18: =VLOOKUP(S18,Data!$B:$E,4,FALSE) -> #N/A | F18: =VLOOKUP(T18,Data!$B:$E,4,FALSE) -> #N/A | G18: =VLOOKUP(U18,Data!$B:$E,4,FALSE) -> #N/A | H18: =VLOOKUP(V18,Data!$B:$E,4,FALSE) -> #N/A | I18: =VLOOKUP(W18,Data!$B:$E,4,FALSE) -> #N/A | J18: =VLOOKUP(X18,Data!$B:$E,4,FALSE) -> #N/A | O18: YZ 250X | P18: A1075 | Q18: A1075.1 | R18: A1075.2 | S18: A1075.8 | T18: A1075.3 | U18: A1075.4 | V18: A1075.5 | W18: A1075.6 | X18: A1075.7
A19: =Translation!A48 -> YZ 450F | B19: A1080 | C19: =VLOOKUP(Q19,Data!$B:$E,4,FALSE) -> #N/A | D19: =VLOOKUP(R19,Data!$B:$E,4,FALSE) -> #N/A | E19: =VLOOKUP(S19,Data!$B:$E,4,FALSE) -> #N/A | F19: =VLOOKUP(T19,Data!$B:$E,4,FALSE) -> #N/A | G19: =VLOOKUP(U19,Data!$B:$E,4,FALSE) -> #N/A | H19: =VLOOKUP(V19,Data!$B:$E,4,FALSE) -> #N/A | I19: =VLOOKUP(W19,Data!$B:$E,4,FALSE) -> #N/A | J19: =VLOOKUP(X19,Data!$B:$E,4,FALSE) -> #N/A | O19: YZ 450F | P19: A1080 | Q19: A1080.1 | R19: A1080.2 | S19: A1080.8 | T19: A1080.3 | U19: A1080.4 | V19: A1080.5 | W19: A1080.6 | X19: A1080.7
A20: YZ 450 FX | B20: A1085 | C20: =VLOOKUP(Q20,Data!$B:$E,4,FALSE) -> #N/A | D20: =VLOOKUP(R20,Data!$B:$E,4,FALSE) -> #N/A | E20: =VLOOKUP(S20,Data!$B:$E,4,FALSE) -> #N/A | F20: =VLOOKUP(T20,Data!$B:$E,4,FALSE) -> #N/A | G20: =VLOOKUP(U20,Data!$B:$E,4,FALSE) -> #N/A | H20: =VLOOKUP(V20,Data!$B:$E,4,FALSE) -> #N/A | I20: =VLOOKUP(W20,Data!$B:$E,4,FALSE) -> #N/A | J20: =VLOOKUP(X20,Data!$B:$E,4,FALSE) -> #N/A | O20: YZ 450 FX | P20: A1085 | Q20: A1085.1 | R20: A1085.2 | S20: A1085.8 | T20: A1085.3 | U20: A1085.4 | V20: A1085.5 | W20: A1085.6 | X20: A1085.7
A21: =Translation!A50 -> WR 250F | B21: A1090 | C21: =VLOOKUP(Q21,Data!$B:$E,4,FALSE) -> #N/A | D21: =VLOOKUP(R21,Data!$B:$E,4,FALSE) -> #N/A | E21: =VLOOKUP(S21,Data!$B:$E,4,FALSE) -> #N/A | F21: =VLOOKUP(T21,Data!$B:$E,4,FALSE) -> #N/A | G21: =VLOOKUP(U21,Data!$B:$E,4,FALSE) -> #N/A | H21: =VLOOKUP(V21,Data!$B:$E,4,FALSE) -> #N/A | I21: =VLOOKUP(W21,Data!$B:$E,4,FALSE) -> #N/A | J21: =VLOOKUP(X21,Data!$B:$E,4,FALSE) -> #N/A | O21: WR 250F | P21: A1090 | Q21: A1090.1 | R21: A1090.2 | S21: A1090.8 | T21: A1090.3 | U21: A1090.4 | V21: A1090.5 | W21: A1090.6 | X21: A1090.7
A22: WR 450F | B22: A1095 | C22: =VLOOKUP(Q22,Data!$B:$E,4,FALSE) -> #N/A | D22: =VLOOKUP(R22,Data!$B:$E,4,FALSE) -> #N/A | E22: =VLOOKUP(S22,Data!$B:$E,4,FALSE) -> #N/A | F22: =VLOOKUP(T22,Data!$B:$E,4,FALSE) -> #N/A | G22: =VLOOKUP(U22,Data!$B:$E,4,FALSE) -> #N/A | H22: =VLOOKUP(V22,Data!$B:$E,4,FALSE) -> #N/A | I22: =VLOOKUP(W22,Data!$B:$E,4,FALSE) -> #N/A | J22: =VLOOKUP(X22,Data!$B:$E,4,FALSE) -> #N/A | O22: WR 450F | P22: A1095 | Q22: A1095.1 | R22: A1095.2 | S22: A1095.8 | T22: A1095.3 | U22: A1095.4 | V22: A1095.5 | W22: A1095.6 | X22: A1095.7
A23: =Translation!A52 -> TOTAL DE VENDAS - LINHA OFF ROAD | B23: A1100 | C23: =VLOOKUP(Q23,Data!$B:$E,4,FALSE) -> #N/A | D23: =VLOOKUP(R23,Data!$B:$E,4,FALSE) -> #N/A | E23: =VLOOKUP(S23,Data!$B:$E,4,FALSE) -> #N/A | F23: =VLOOKUP(T23,Data!$B:$E,4,FALSE) -> #N/A | G23: =VLOOKUP(U23,Data!$B:$E,4,FALSE) -> #N/A | H23: =VLOOKUP(V23,Data!$B:$E,4,FALSE) -> #N/A | I23: =VLOOKUP(W23,Data!$B:$E,4,FALSE) -> #N/A | J23: =VLOOKUP(X23,Data!$B:$E,4,FALSE) -> #N/A | O23: TOTAL DE VENDAS - LINHA OFF ROAD | P23: A1100 | Q23: A1100.1 | R23: A1100.2 | S23: A1100.8 | T23: A1100.3 | U23: A1100.4 | V23: A1100.5 | W23: A1100.6 | X23: A1100.7
A24: =Translation!A53 -> LINHA 125 cc | B24: =Translation!$G$32 -> CONTA | C24: =Translation!$G$12 -> UNIDADES | D24: =Translation!$G$11 -> RECEITA (SEM IMPOSTOS) | E24: =Translation!$G$33 -> UNIDADES DEVOLVIDAS | F24: =Translation!$G$14 -> DEVOLUÇÃO DE VENDAS | G24: =Translation!$G$3 -> ABAT. E DESCONTO | H24: =Translation!$G$9 -> RECEITA LÍQUIDA | I24: =Translation!$G$2 -> CUSTO | J24: =Translation!$G$5 -> LUCRO BRUTO | O24: LINHA 125 cc | P24: =Translation!$G$32 -> CONTA | Q24: UNITS | R24: SALES | S24: URETURN | T24: SC | U24: DISC | V24: NS | W24: COS | X24: GP
A25: =Translation!A54 -> FACTOR YBR 125i ED | B25: A1110 | C25: =VLOOKUP(Q25,Data!$B:$E,4,FALSE) -> #N/A | D25: =VLOOKUP(R25,Data!$B:$E,4,FALSE) -> #N/A | E25: =VLOOKUP(S25,Data!$B:$E,4,FALSE) -> #N/A | F25: =VLOOKUP(T25,Data!$B:$E,4,FALSE) -> #N/A | G25: =VLOOKUP(U25,Data!$B:$E,4,FALSE) -> #N/A | H25: =VLOOKUP(V25,Data!$B:$E,4,FALSE) -> #N/A | I25: =VLOOKUP(W25,Data!$B:$E,4,FALSE) -> #N/A | J25: =VLOOKUP(X25,Data!$B:$E,4,FALSE) -> #N/A | O25: FACTOR YBR 125i ED | P25: A1110 | Q25: A1110.1 | R25: A1110.2 | S25: A1110.8 | T25: A1110.3 | U25: A1110.4 | V25: A1110.5 | W25: A1110.6 | X25: A1110.7
A26: FLUO ABS | B26: A1111 | C26: =VLOOKUP(Q26,Data!$B:$E,4,FALSE) -> #N/A | D26: =VLOOKUP(R26,Data!$B:$E,4,FALSE) -> #N/A | E26: =VLOOKUP(S26,Data!$B:$E,4,FALSE) -> #N/A | F26: =VLOOKUP(T26,Data!$B:$E,4,FALSE) -> #N/A | G26: =VLOOKUP(U26,Data!$B:$E,4,FALSE) -> #N/A | H26: =VLOOKUP(V26,Data!$B:$E,4,FALSE) -> #N/A | I26: =VLOOKUP(W26,Data!$B:$E,4,FALSE) -> #N/A | J26: =VLOOKUP(X26,Data!$B:$E,4,FALSE) -> #N/A | O26: FLUO ABS | P26: A1111 | Q26: A1111.1 | R26: A1111.2 | S26: A1111.8 | T26: A1111.3 | U26: A1111.4 | V26: A1111.5 | W26: A1111.6 | X26: A1111.7
A27: =Translation!A55 -> TOTAL DE VENDAS - LINHA 125 cc | B27: A1120 | C27: =VLOOKUP(Q27,Data!$B:$E,4,FALSE) -> #N/A | D27: =VLOOKUP(R27,Data!$B:$E,4,FALSE) -> #N/A | E27: =VLOOKUP(S27,Data!$B:$E,4,FALSE) -> #N/A | F27: =VLOOKUP(T27,Data!$B:$E,4,FALSE) -> #N/A | G27: =VLOOKUP(U27,Data!$B:$E,4,FALSE) -> #N/A | H27: =VLOOKUP(V27,Data!$B:$E,4,FALSE) -> #N/A | I27: =VLOOKUP(W27,Data!$B:$E,4,FALSE) -> #N/A | J27: =VLOOKUP(X27,Data!$B:$E,4,FALSE) -> #N/A | O27: TOTAL DE VENDAS - LINHA 125 cc | P27: A1120 | Q27: A1120.1 | R27: A1120.2 | S27: A1120.8 | T27: A1120.3 | U27: A1120.4 | V27: A1120.5 | W27: A1120.6 | X27: A1120.7
A28: =Translation!A56 -> LINHA 150 cc - Street | B28: =Translation!$G$32 -> CONTA | C28: =Translation!$G$12 -> UNIDADES | D28: =Translation!$G$11 -> RECEITA (SEM IMPOSTOS) | E28: =Translation!$G$33 -> UNIDADES DEVOLVIDAS | F28: =Translation!$G$14 -> DEVOLUÇÃO DE VENDAS | G28: =Translation!$G$3 -> ABAT. E DESCONTO | H28: =Translation!$G$9 -> RECEITA LÍQUIDA | I28: =Translation!$G$2 -> CUSTO | J28: =Translation!$G$5 -> LUCRO BRUTO | O28: LINHA 150 cc - Street | P28: =Translation!$G$32 -> CONTA | Q28: UNITS | R28: SALES | S28: URETURN | T28: SC | U28: DISC | V28: NS | W28: COS | X28: GP
A29: =Translation!A57 -> FACTOR 150E | B29: A1130 | C29: =VLOOKUP(Q29,Data!$B:$E,4,FALSE) -> #N/A | D29: =VLOOKUP(R29,Data!$B:$E,4,FALSE) -> #N/A | E29: =VLOOKUP(S29,Data!$B:$E,4,FALSE) -> #N/A | F29: =VLOOKUP(T29,Data!$B:$E,4,FALSE) -> #N/A | G29: =VLOOKUP(U29,Data!$B:$E,4,FALSE) -> #N/A | H29: =VLOOKUP(V29,Data!$B:$E,4,FALSE) -> #N/A | I29: =VLOOKUP(W29,Data!$B:$E,4,FALSE) -> #N/A | J29: =VLOOKUP(X29,Data!$B:$E,4,FALSE) -> #N/A | O29: FACTOR 150E | P29: A1130 | Q29: A1130.1 | R29: A1130.2 | S29: A1130.8 | T29: A1130.3 | U29: A1130.4 | V29: A1130.5 | W29: A1130.6 | X29: A1130.7
A30: =Translation!A58 -> FACTOR 150ED | B30: A1140 | C30: =VLOOKUP(Q30,Data!$B:$E,4,FALSE) -> #N/A | D30: =VLOOKUP(R30,Data!$B:$E,4,FALSE) -> #N/A | E30: =VLOOKUP(S30,Data!$B:$E,4,FALSE) -> #N/A | F30: =VLOOKUP(T30,Data!$B:$E,4,FALSE) -> #N/A | G30: =VLOOKUP(U30,Data!$B:$E,4,FALSE) -> #N/A | H30: =VLOOKUP(V30,Data!$B:$E,4,FALSE) -> #N/A | I30: =VLOOKUP(W30,Data!$B:$E,4,FALSE) -> #N/A | J30: =VLOOKUP(X30,Data!$B:$E,4,FALSE) -> #N/A | O30: FACTOR 150ED | P30: A1140 | Q30: A1140.1 | R30: A1140.2 | S30: A1140.8 | T30: A1140.3 | U30: A1140.4 | V30: A1140.5 | W30: A1140.6 | X30: A1140.7
A31: =Translation!A59 -> YS 150 FAZER SED | B31: A1150 | C31: =VLOOKUP(Q31,Data!$B:$E,4,FALSE) -> #N/A | D31: =VLOOKUP(R31,Data!$B:$E,4,FALSE) -> #N/A | E31: =VLOOKUP(S31,Data!$B:$E,4,FALSE) -> #N/A | F31: =VLOOKUP(T31,Data!$B:$E,4,FALSE) -> #N/A | G31: =VLOOKUP(U31,Data!$B:$E,4,FALSE) -> #N/A | H31: =VLOOKUP(V31,Data!$B:$E,4,FALSE) -> #N/A | I31: =VLOOKUP(W31,Data!$B:$E,4,FALSE) -> #N/A | J31: =VLOOKUP(X31,Data!$B:$E,4,FALSE) -> #N/A | O31: YS 150 FAZER SED | P31: A1150 | Q31: A1150.1 | R31: A1150.2 | S31: A1150.8 | T31: A1150.3 | U31: A1150.4 | V31: A1150.5 | W31: A1150.6 | X31: A1150.7
A32: YZF R15 ABS | B32: A1151 | C32: =VLOOKUP(Q32,Data!$B:$E,4,FALSE) -> #N/A | D32: =VLOOKUP(R32,Data!$B:$E,4,FALSE) -> #N/A | E32: =VLOOKUP(S32,Data!$B:$E,4,FALSE) -> #N/A | F32: =VLOOKUP(T32,Data!$B:$E,4,FALSE) -> #N/A | G32: =VLOOKUP(U32,Data!$B:$E,4,FALSE) -> #N/A | H32: =VLOOKUP(V32,Data!$B:$E,4,FALSE) -> #N/A | I32: =VLOOKUP(W32,Data!$B:$E,4,FALSE) -> #N/A | J32: =VLOOKUP(X32,Data!$B:$E,4,FALSE) -> #N/A | O32: YZF R15 ABS | P32: A1151 | Q32: A1151.1 | R32: A1151.2 | S32: A1151.8 | T32: A1151.3 | U32: A1151.4 | V32: A1151.5 | W32: A1151.6 | X32: A1151.7
A33: FZ15 FAZER ABS | B33: A1152 | C33: =VLOOKUP(Q33,Data!$B:$E,4,FALSE) -> #N/A | D33: =VLOOKUP(R33,Data!$B:$E,4,FALSE) -> #N/A | E33: =VLOOKUP(S33,Data!$B:$E,4,FALSE) -> #N/A | F33: =VLOOKUP(T33,Data!$B:$E,4,FALSE) -> #N/A | G33: =VLOOKUP(U33,Data!$B:$E,4,FALSE) -> #N/A | H33: =VLOOKUP(V33,Data!$B:$E,4,FALSE) -> #N/A | I33: =VLOOKUP(W33,Data!$B:$E,4,FALSE) -> #N/A | J33: =VLOOKUP(X33,Data!$B:$E,4,FALSE) -> #N/A | O33: FZ15 FAZER ABS | P33: A1152 | Q33: A1152.1 | R33: A1152.2 | S33: A1152.8 | T33: A1152.3 | U33: A1152.4 | V33: A1152.5 | W33: A1152.6 | X33: A1152.7
A34: =Translation!A60 -> LINHA 150 cc - On/Off | B34: =Translation!$G$32 -> CONTA | C34: =Translation!$G$12 -> UNIDADES | D34: =Translation!$G$11 -> RECEITA (SEM IMPOSTOS) | E34: =Translation!$G$33 -> UNIDADES DEVOLVIDAS | F34: =Translation!$G$14 -> DEVOLUÇÃO DE VENDAS | G34: =Translation!$G$3 -> ABAT. E DESCONTO | H34: =Translation!$G$9 -> RECEITA LÍQUIDA | I34: =Translation!$G$2 -> CUSTO | J34: =Translation!$G$5 -> LUCRO BRUTO | O34: LINHA 150 cc - On/Off | P34: =Translation!$G$32 -> CONTA | Q34: UNITS | R34: SALES | S34: URETURN | T34: SC | U34: DISC | V34: NS | W34: COS | X34: GP
A35: =Translation!A61 -> XTZ 150 CROSSER E | B35: A1160 | C35: =VLOOKUP(Q35,Data!$B:$E,4,FALSE) -> #N/A | D35: =VLOOKUP(R35,Data!$B:$E,4,FALSE) -> #N/A | E35: =VLOOKUP(S35,Data!$B:$E,4,FALSE) -> #N/A | F35: =VLOOKUP(T35,Data!$B:$E,4,FALSE) -> #N/A | G35: =VLOOKUP(U35,Data!$B:$E,4,FALSE) -> #N/A | H35: =VLOOKUP(V35,Data!$B:$E,4,FALSE) -> #N/A | I35: =VLOOKUP(W35,Data!$B:$E,4,FALSE) -> #N/A | J35: =VLOOKUP(X35,Data!$B:$E,4,FALSE) -> #N/A | O35: XTZ 150 CROSSER E | P35: A1160 | Q35: A1160.1 | R35: A1160.2 | S35: A1160.8 | T35: A1160.3 | U35: A1160.4 | V35: A1160.5 | W35: A1160.6 | X35: A1160.7
A36: =Translation!A62 -> XTZ 150 CROSSER ED | B36: A1170 | C36: =VLOOKUP(Q36,Data!$B:$E,4,FALSE) -> #N/A | D36: =VLOOKUP(R36,Data!$B:$E,4,FALSE) -> #N/A | E36: =VLOOKUP(S36,Data!$B:$E,4,FALSE) -> #N/A | F36: =VLOOKUP(T36,Data!$B:$E,4,FALSE) -> #N/A | G36: =VLOOKUP(U36,Data!$B:$E,4,FALSE) -> #N/A | H36: =VLOOKUP(V36,Data!$B:$E,4,FALSE) -> #N/A | I36: =VLOOKUP(W36,Data!$B:$E,4,FALSE) -> #N/A | J36: =VLOOKUP(X36,Data!$B:$E,4,FALSE) -> #N/A | O36: XTZ 150 CROSSER ED | P36: A1170 | Q36: A1170.1 | R36: A1170.2 | S36: A1170.8 | T36: A1170.3 | U36: A1170.4 | V36: A1170.5 | W36: A1170.6 | X36: A1170.7
A37: XTZ 150 CROSSER S | B37: A1174 | C37: =VLOOKUP(Q37,Data!$B:$E,4,FALSE) -> #N/A | D37: =VLOOKUP(R37,Data!$B:$E,4,FALSE) -> #N/A | E37: =VLOOKUP(S37,Data!$B:$E,4,FALSE) -> #N/A | F37: =VLOOKUP(T37,Data!$B:$E,4,FALSE) -> #N/A | G37: =VLOOKUP(U37,Data!$B:$E,4,FALSE) -> #N/A | H37: =VLOOKUP(V37,Data!$B:$E,4,FALSE) -> #N/A | I37: =VLOOKUP(W37,Data!$B:$E,4,FALSE) -> #N/A | J37: =VLOOKUP(X37,Data!$B:$E,4,FALSE) -> #N/A | O37: XTZ 150 CROSSER S | P37: A1174 | Q37: A1174.1 | R37: A1174.2 | S37: A1174.8 | T37: A1174.3 | U37: A1174.4 | V37: A1174.5 | W37: A1174.6 | X37: A1174.7
A38: XTZ 150 CROSSER Z | B38: A1176 | C38: =VLOOKUP(Q38,Data!$B:$E,4,FALSE) -> #N/A | D38: =VLOOKUP(R38,Data!$B:$E,4,FALSE) -> #N/A | E38: =VLOOKUP(S38,Data!$B:$E,4,FALSE) -> #N/A | F38: =VLOOKUP(T38,Data!$B:$E,4,FALSE) -> #N/A | G38: =VLOOKUP(U38,Data!$B:$E,4,FALSE) -> #N/A | H38: =VLOOKUP(V38,Data!$B:$E,4,FALSE) -> #N/A | I38: =VLOOKUP(W38,Data!$B:$E,4,FALSE) -> #N/A | J38: =VLOOKUP(X38,Data!$B:$E,4,FALSE) -> #N/A | O38: XTZ 150 CROSSER Z | P38: A1176 | Q38: A1176.1 | R38: A1176.2 | S38: A1176.8 | T38: A1176.3 | U38: A1176.4 | V38: A1176.5 | W38: A1176.6 | X38: A1176.7
A39: =Translation!A63 -> TOTAL DE VENDAS - LINHA 150 cc | B39: A1180 | C39: =VLOOKUP(Q39,Data!$B:$E,4,FALSE) -> #N/A | D39: =VLOOKUP(R39,Data!$B:$E,4,FALSE) -> #N/A | E39: =VLOOKUP(S39,Data!$B:$E,4,FALSE) -> #N/A | F39: =VLOOKUP(T39,Data!$B:$E,4,FALSE) -> #N/A | G39: =VLOOKUP(U39,Data!$B:$E,4,FALSE) -> #N/A | H39: =VLOOKUP(V39,Data!$B:$E,4,FALSE) -> #N/A | I39: =VLOOKUP(W39,Data!$B:$E,4,FALSE) -> #N/A | J39: =VLOOKUP(X39,Data!$B:$E,4,FALSE) -> #N/A | O39: TOTAL DE VENDAS - LINHA 150 cc | P39: A1180 | Q39: A1180.1 | R39: A1180.2 | S39: A1180.8 | T39: A1180.3 | U39: A1180.4 | V39: A1180.5 | W39: A1180.6 | X39: A1180.7
A40: =Translation!A64 -> LINHA 250 cc - Street | B40: =Translation!$G$32 -> CONTA | C40: =Translation!$G$12 -> UNIDADES | D40: =Translation!$G$11 -> RECEITA (SEM IMPOSTOS) | E40: =Translation!$G$33 -> UNIDADES DEVOLVIDAS | F40: =Translation!$G$14 -> DEVOLUÇÃO DE VENDAS | G40: =Translation!$G$3 -> ABAT. E DESCONTO | H40: =Translation!$G$9 -> RECEITA LÍQUIDA | I40: =Translation!$G$2 -> CUSTO | J40: =Translation!$G$5 -> LUCRO BRUTO | O40: LINHA 250 cc - Street | P40: =Translation!$G$32 -> CONTA | Q40: UNITS | R40: SALES | S40: URETURN | T40: SC | U40: DISC | V40: NS | W40: COS | X40: GP
...

Sheet DRE Mês
A1: =Translation!$A$23 -> DRE YAMAHA BMI - Mês
A2: =Translation!$A$20&Data!D1 -> Concessionário: %%=$RecordSet.#4 | C2: =Translation!$A$19&Data!D3 -> Localização: %%=$RecordSet.#8 | H2: =Translation!$A$21 -> Período: | I2: =VLOOKUP(Data!D6,Data!H1:I12,2,FALSE)&" "&Data!E6 -> #N/A
A3: =Translation!A1 -> VENDA DE NOVOS | O3: VENDA NOVOS
A4: =Translation!A35 -> LINHA SCOOTER <200 cc | B4: =Translation!$G$32 -> CONTA | C4: =Translation!$G$12 -> UNIDADES | D4: =Translation!$G$11 -> RECEITA (SEM IMPOSTOS) | E4: =Translation!$G$33 -> UNIDADES DEVOLVIDAS | F4: =Translation!$G$14 -> DEVOLUÇÃO DE VENDAS | G4: =Translation!$G$3 -> ABAT. E DESCONTO | H4: =Translation!$G$9 -> RECEITA LÍQUIDA | I4: =Translation!$G$2 -> CUSTO | J4: =Translation!$G$5 -> LUCRO BRUTO | O4: LINHA SCOOTER <200 cc | P4: =Translation!$G$32 -> CONTA | Q4: UNITS | R4: SALES | S4: URETURN | T4: SC | U4: DISC | V4: NS | W4: COS | X4: GP
A5: =Translation!A36 -> NEO 125 | B5: A1000 | C5: =VLOOKUP(Q5,Data!$B:$E,3,FALSE) -> #N/A | D5: =VLOOKUP(R5,Data!$B:$E,3,FALSE) -> #N/A | E5: =VLOOKUP(S5,Data!$B:$E,3,FALSE) -> #N/A | F5: =VLOOKUP(T5,Data!$B:$E,3,FALSE) -> #N/A | G5: =VLOOKUP(U5,Data!$B:$E,3,FALSE) -> #N/A | H5: =VLOOKUP(V5,Data!$B:$E,3,FALSE) -> #N/A | I5: =VLOOKUP(W5,Data!$B:$E,3,FALSE) -> #N/A | J5: =VLOOKUP(X5,Data!$B:$E,3,FALSE) -> #N/A | O5: NEO 125 | P5: A1000 | Q5: A1000.1 | R5: A1000.2 | S5: A1000.8 | T5: A1000.3 | U5: A1000.4 | V5: A1000.5 | W5: A1000.6 | X5: A1000.7
A6: =Translation!A37 -> NMAX 160 ABS | B6: A1010 | C6: =VLOOKUP(Q6,Data!$B:$E,3,FALSE) -> #N/A | D6: =VLOOKUP(R6,Data!$B:$E,3,FALSE) -> #N/A | E6: =VLOOKUP(S6,Data!$B:$E,3,FALSE) -> #N/A | F6: =VLOOKUP(T6,Data!$B:$E,3,FALSE) -> #N/A | G6: =VLOOKUP(U6,Data!$B:$E,3,FALSE) -> #N/A | H6: =VLOOKUP(V6,Data!$B:$E,3,FALSE) -> #N/A | I6: =VLOOKUP(W6,Data!$B:$E,3,FALSE) -> #N/A | J6: =VLOOKUP(X6,Data!$B:$E,3,FALSE) -> #N/A | O6: NMAX 160 ABS | P6: A1010 | Q6: A1010.1 | R6: A1010.2 | S6: A1010.8 | T6: A1010.3 | U6: A1010.4 | V6: A1010.5 | W6: A1010.6 | X6: A1010.7
A7: =Translation!A38 -> LINHA SCOOTER >200 cc | B7: =Translation!$G$32 -> CONTA | C7: =Translation!$G$12 -> UNIDADES | D7: =Translation!$G$11 -> RECEITA (SEM IMPOSTOS) | E7: =Translation!$G$33 -> UNIDADES DEVOLVIDAS | F7: =Translation!$G$14 -> DEVOLUÇÃO DE VENDAS | G7: =Translation!$G$3 -> ABAT. E DESCONTO | H7: =Translation!$G$9 -> RECEITA LÍQUIDA | I7: =Translation!$G$2 -> CUSTO | J7: =Translation!$G$5 -> LUCRO BRUTO | O7: LINHA SCOOTER >200 cc | P7: =Translation!$G$32 -> CONTA | Q7: UNITS | R7: SALES | S7: URETURN | T7: SC | U7: DISC | V7: NS | W7: COS | X7: GP
A8: =Translation!A39 -> TMAX 530 | B8: A1020 | C8: =VLOOKUP(Q8,Data!$B:$E,3,FALSE) -> #N/A | D8: =VLOOKUP(R8,Data!$B:$E,3,FALSE) -> #N/A | E8: =VLOOKUP(S8,Data!$B:$E,3,FALSE) -> #N/A | F8: =VLOOKUP(T8,Data!$B:$E,3,FALSE) -> #N/A | G8: =VLOOKUP(U8,Data!$B:$E,3,FALSE) -> #N/A | H8: =VLOOKUP(V8,Data!$B:$E,3,FALSE) -> #N/A | I8: =VLOOKUP(W8,Data!$B:$E,3,FALSE) -> #N/A | J8: =VLOOKUP(X8,Data!$B:$E,3,FALSE) -> #N/A | O8: TMAX 530 | P8: A1020 | Q8: A1020.1 | R8: A1020.2 | S8: A1020.8 | T8: A1020.3 | U8: A1020.4 | V8: A1020.5 | W8: A1020.6 | X8: A1020.7
A9: X MAX ABS | B9: A1021 | C9: =VLOOKUP(Q9,Data!$B:$E,3,FALSE) -> #N/A | D9: =VLOOKUP(R9,Data!$B:$E,3,FALSE) -> #N/A | E9: =VLOOKUP(S9,Data!$B:$E,3,FALSE) -> #N/A | F9: =VLOOKUP(T9,Data!$B:$E,3,FALSE) -> #N/A | G9: =VLOOKUP(U9,Data!$B:$E,3,FALSE) -> #N/A | H9: =VLOOKUP(V9,Data!$B:$E,3,FALSE) -> #N/A | I9: =VLOOKUP(W9,Data!$B:$E,3,FALSE) -> #N/A | J9: =VLOOKUP(X9,Data!$B:$E,3,FALSE) -> #N/A | O9: X MAX ABS | P9: A1021 | Q9: A1021.1 | R9: A1021.2 | S9: A1021.8 | T9: A1021.3 | U9: A1021.4 | V9: A1021.5 | W9: A1021.6 | X9: A1021.7
A10: NEOS CONNECTED | B10: A1022 | C10: =VLOOKUP(Q10,Data!$B:$E,3,FALSE) -> #N/A | D10: =VLOOKUP(R10,Data!$B:$E,3,FALSE) -> #N/A | E10: =VLOOKUP(S10,Data!$B:$E,3,FALSE) -> #N/A | F10: =VLOOKUP(T10,Data!$B:$E,3,FALSE) -> #N/A | G10: =VLOOKUP(U10,Data!$B:$E,3,FALSE) -> #N/A | H10: =VLOOKUP(V10,Data!$B:$E,3,FALSE) -> #N/A | I10: =VLOOKUP(W10,Data!$B:$E,3,FALSE) -> #N/A | J10: =VLOOKUP(X10,Data!$B:$E,3,FALSE) -> #N/A | O10: NEOS CONNECTED | P10: A1022 | Q10: A1022.1 | R10: A1022.2 | S10: A1022.8 | T10: A1022.3 | U10: A1022.4 | V10: A1022.5 | W10: A1022.6 | X10: A1022.7
A11: =Translation!A40 -> TOTAL DE VENDAS - SCOOTER | B11: A1030 | C11: =VLOOKUP(Q11,Data!$B:$E,3,FALSE) -> #N/A | D11: =VLOOKUP(R11,Data!$B:$E,3,FALSE) -> #N/A | E11: =VLOOKUP(S11,Data!$B:$E,3,FALSE) -> #N/A | F11: =VLOOKUP(T11,Data!$B:$E,3,FALSE) -> #N/A | G11: =VLOOKUP(U11,Data!$B:$E,3,FALSE) -> #N/A | H11: =VLOOKUP(V11,Data!$B:$E,3,FALSE) -> #N/A | I11: =VLOOKUP(W11,Data!$B:$E,3,FALSE) -> #N/A | J11: =VLOOKUP(X11,Data!$B:$E,3,FALSE) -> #N/A | O11: TOTAL DE VENDAS - SCOOTER | P11: A1030 | Q11: A1030.1 | R11: A1030.2 | S11: A1030.8 | T11: A1030.3 | U11: A1030.4 | V11: A1030.5 | W11: A1030.6 | X11: A1030.7
A12: =Translation!A41 -> LINHA OFF ROAD | B12: =Translation!$G$32 -> CONTA | C12: =Translation!$G$12 -> UNIDADES | D12: =Translation!$G$11 -> RECEITA (SEM IMPOSTOS) | E12: =Translation!$G$33 -> UNIDADES DEVOLVIDAS | F12: =Translation!$G$14 -> DEVOLUÇÃO DE VENDAS | G12: =Translation!$G$3 -> ABAT. E DESCONTO | H12: =Translation!$G$9 -> RECEITA LÍQUIDA | I12: =Translation!$G$2 -> CUSTO | J12: =Translation!$G$5 -> LUCRO BRUTO | O12: LINHA OFF ROAD | P12: =Translation!$G$32 -> CONTA | Q12: UNITS | R12: SALES | S12: URETURN | T12: SC | U12: DISC | V12: NS | W12: COS | X12: GP
A13: =Translation!A42 -> TTR 230 | B13: A1040 | C13: =VLOOKUP(Q13,Data!$B:$E,3,FALSE) -> #N/A | D13: =VLOOKUP(R13,Data!$B:$E,3,FALSE) -> #N/A | E13: =VLOOKUP(S13,Data!$B:$E,3,FALSE) -> #N/A | F13: =VLOOKUP(T13,Data!$B:$E,3,FALSE) -> #N/A | G13: =VLOOKUP(U13,Data!$B:$E,3,FALSE) -> #N/A | H13: =VLOOKUP(V13,Data!$B:$E,3,FALSE) -> #N/A | I13: =VLOOKUP(W13,Data!$B:$E,3,FALSE) -> #N/A | J13: =VLOOKUP(X13,Data!$B:$E,3,FALSE) -> #N/A | O13: TTR 230 | P13: A1040 | Q13: A1040.1 | R13: A1040.2 | S13: A1040.8 | T13: A1040.3 | U13: A1040.4 | V13: A1040.5 | W13: A1040.6 | X13: A1040.7
A14: YZ 85LW | B14: A1045 | C14: =VLOOKUP(Q14,Data!$B:$E,3,FALSE) -> #N/A | D14: =VLOOKUP(R14,Data!$B:$E,3,FALSE) -> #N/A | E14: =VLOOKUP(S14,Data!$B:$E,3,FALSE) -> #N/A | F14: =VLOOKUP(T14,Data!$B:$E,3,FALSE) -> #N/A | G14: =VLOOKUP(U14,Data!$B:$E,3,FALSE) -> #N/A | H14: =VLOOKUP(V14,Data!$B:$E,3,FALSE) -> #N/A | I14: =VLOOKUP(W14,Data!$B:$E,3,FALSE) -> #N/A | J14: =VLOOKUP(X14,Data!$B:$E,3,FALSE) -> #N/A | O14: YZ 85LW | P14: A1045 | Q14: A1045.1 | R14: A1045.2 | S14: A1045.8 | T14: A1045.3 | U14: A1045.4 | V14: A1045.5 | W14: A1045.6 | X14: A1045.7
A15: =Translation!A44 -> YZ 250 | B15: A1050 | C15: =VLOOKUP(Q15,Data!$B:$E,3,FALSE) -> #N/A | D15: =VLOOKUP(R15,Data!$B:$E,3,FALSE) -> #N/A | E15: =VLOOKUP(S15,Data!$B:$E,3,FALSE) -> #N/A | F15: =VLOOKUP(T15,Data!$B:$E,3,FALSE) -> #N/A | G15: =VLOOKUP(U15,Data!$B:$E,3,FALSE) -> #N/A | H15: =VLOOKUP(V15,Data!$B:$E,3,FALSE) -> #N/A | I15: =VLOOKUP(W15,Data!$B:$E,3,FALSE) -> #N/A | J15: =VLOOKUP(X15,Data!$B:$E,3,FALSE) -> #N/A | O15: YZ 250 | P15: A1050 | Q15: A1050.1 | R15: A1050.2 | S15: A1050.8 | T15: A1050.3 | U15: A1050.4 | V15: A1050.5 | W15: A1050.6 | X15: A1050.7
A16: =Translation!A45 -> YZ 250F | B16: A1060 | C16: =VLOOKUP(Q16,Data!$B:$E,3,FALSE) -> #N/A | D16: =VLOOKUP(R16,Data!$B:$E,3,FALSE) -> #N/A | E16: =VLOOKUP(S16,Data!$B:$E,3,FALSE) -> #N/A | F16: =VLOOKUP(T16,Data!$B:$E,3,FALSE) -> #N/A | G16: =VLOOKUP(U16,Data!$B:$E,3,FALSE) -> #N/A | H16: =VLOOKUP(V16,Data!$B:$E,3,FALSE) -> #N/A | I16: =VLOOKUP(W16,Data!$B:$E,3,FALSE) -> #N/A | J16: =VLOOKUP(X16,Data!$B:$E,3,FALSE) -> #N/A | O16: YZ 250F | P16: A1060 | Q16: A1060.1 | R16: A1060.2 | S16: A1060.8 | T16: A1060.3 | U16: A1060.4 | V16: A1060.5 | W16: A1060.6 | X16: A1060.7
A17: =Translation!A46 -> YZ 250FX | B17: A1070 | C17: =VLOOKUP(Q17,Data!$B:$E,3,FALSE) -> #N/A | D17: =VLOOKUP(R17,Data!$B:$E,3,FALSE) -> #N/A | E17: =VLOOKUP(S17,Data!$B:$E,3,FALSE) -> #N/A | F17: =VLOOKUP(T17,Data!$B:$E,3,FALSE) -> #N/A | G17: =VLOOKUP(U17,Data!$B:$E,3,FALSE) -> #N/A | H17: =VLOOKUP(V17,Data!$B:$E,3,FALSE) -> #N/A | I17: =VLOOKUP(W17,Data!$B:$E,3,FALSE) -> #N/A | J17: =VLOOKUP(X17,Data!$B:$E,3,FALSE) -> #N/A | O17: YZ 250FX | P17: A1070 | Q17: A1070.1 | R17: A1070.2 | S17: A1070.8 | T17: A1070.3 | U17: A1070.4 | V17: A1070.5 | W17: A1070.6 | X17: A1070.7
A18: YZ 250X | B18: A1075 | C18: =VLOOKUP(Q18,Data!$B:$E,3,FALSE) -> #N/A | D18: =VLOOKUP(R18,Data!$B:$E,3,FALSE) -> #N/A | E18: =VLOOKUP(S18,Data!$B:$E,3,FALSE) -> #N/A | F18: =VLOOKUP(T18,Data!$B:$E,3,FALSE) -> #N/A | G18: =VLOOKUP(U18,Data!$B:$E,3,FALSE) -> #N/A | H18: =VLOOKUP(V18,Data!$B:$E,3,FALSE) -> #N/A | I18: =VLOOKUP(W18,Data!$B:$E,3,FALSE) -> #N/A | J18: =VLOOKUP(X18,Data!$B:$E,3,FALSE) -> #N/A | O18: YZ 250X | P18: A1075 | Q18: A1075.1 | R18: A1075.2 | S18: A1075.8 | T18: A1075.3 | U18: A1075.4 | V18: A1075.5 | W18: A1075.6 | X18: A1075.7
A19: =Translation!A48 -> YZ 450F | B19: A1080 | C19: =VLOOKUP(Q19,Data!$B:$E,3,FALSE) -> #N/A | D19: =VLOOKUP(R19,Data!$B:$E,3,FALSE) -> #N/A | E19: =VLOOKUP(S19,Data!$B:$E,3,FALSE) -> #N/A | F19: =VLOOKUP(T19,Data!$B:$E,3,FALSE) -> #N/A | G19: =VLOOKUP(U19,Data!$B:$E,3,FALSE) -> #N/A | H19: =VLOOKUP(V19,Data!$B:$E,3,FALSE) -> #N/A | I19: =VLOOKUP(W19,Data!$B:$E,3,FALSE) -> #N/A | J19: =VLOOKUP(X19,Data!$B:$E,3,FALSE) -> #N/A | O19: YZ 450F | P19: A1080 | Q19: A1080.1 | R19: A1080.2 | S19: A1080.8 | T19: A1080.3 | U19: A1080.4 | V19: A1080.5 | W19: A1080.6 | X19: A1080.7
A20: YZ 450 FX | B20: A1085 | C20: =VLOOKUP(Q20,Data!$B:$E,3,FALSE) -> #N/A | D20: =VLOOKUP(R20,Data!$B:$E,3,FALSE) -> #N/A | E20: =VLOOKUP(S20,Data!$B:$E,3,FALSE) -> #N/A | F20: =VLOOKUP(T20,Data!$B:$E,3,FALSE) -> #N/A | G20: =VLOOKUP(U20,Data!$B:$E,3,FALSE) -> #N/A | H20: =VLOOKUP(V20,Data!$B:$E,3,FALSE) -> #N/A | I20: =VLOOKUP(W20,Data!$B:$E,3,FALSE) -> #N/A | J20: =VLOOKUP(X20,Data!$B:$E,3,FALSE) -> #N/A | O20: YZ 450 FX | P20: A1085 | Q20: A1085.1 | R20: A1085.2 | S20: A1085.8 | T20: A1085.3 | U20: A1085.4 | V20: A1085.5 | W20: A1085.6 | X20: A1085.7
A21: =Translation!A50 -> WR 250F | B21: A1090 | C21: =VLOOKUP(Q21,Data!$B:$E,3,FALSE) -> #N/A | D21: =VLOOKUP(R21,Data!$B:$E,3,FALSE) -> #N/A | E21: =VLOOKUP(S21,Data!$B:$E,3,FALSE) -> #N/A | F21: =VLOOKUP(T21,Data!$B:$E,3,FALSE) -> #N/A | G21: =VLOOKUP(U21,Data!$B:$E,3,FALSE) -> #N/A | H21: =VLOOKUP(V21,Data!$B:$E,3,FALSE) -> #N/A | I21: =VLOOKUP(W21,Data!$B:$E,3,FALSE) -> #N/A | J21: =VLOOKUP(X21,Data!$B:$E,3,FALSE) -> #N/A | O21: WR 250F | P21: A1090 | Q21: A1090.1 | R21: A1090.2 | S21: A1090.8 | T21: A1090.3 | U21: A1090.4 | V21: A1090.5 | W21: A1090.6 | X21: A1090.7
A22: WR 450F | B22: A1095 | C22: =VLOOKUP(Q22,Data!$B:$E,3,FALSE) -> #N/A | D22: =VLOOKUP(R22,Data!$B:$E,3,FALSE) -> #N/A | E22: =VLOOKUP(S22,Data!$B:$E,3,FALSE) -> #N/A | F22: =VLOOKUP(T22,Data!$B:$E,3,FALSE) -> #N/A | G22: =VLOOKUP(U22,Data!$B:$E,3,FALSE) -> #N/A | H22: =VLOOKUP(V22,Data!$B:$E,3,FALSE) -> #N/A | I22: =VLOOKUP(W22,Data!$B:$E,3,FALSE) -> #N/A | J22: =VLOOKUP(X22,Data!$B:$E,3,FALSE) -> #N/A | O22: WR 450F | P22: A1095 | Q22: A1095.1 | R22: A1095.2 | S22: A1095.8 | T22: A1095.3 | U22: A1095.4 | V22: A1095.5 | W22: A1095.6 | X22: A1095.7
A23: =Translation!A52 -> TOTAL DE VENDAS - LINHA OFF ROAD | B23: A1100 | C23: =VLOOKUP(Q23,Data!$B:$E,3,FALSE) -> #N/A | D23: =VLOOKUP(R23,Data!$B:$E,3,FALSE) -> #N/A | E23: =VLOOKUP(S23,Data!$B:$E,3,FALSE) -> #N/A | F23: =VLOOKUP(T23,Data!$B:$E,3,FALSE) -> #N/A | G23: =VLOOKUP(U23,Data!$B:$E,3,FALSE) -> #N/A | H23: =VLOOKUP(V23,Data!$B:$E,3,FALSE) -> #N/A | I23: =VLOOKUP(W23,Data!$B:$E,3,FALSE) -> #N/A | J23: =VLOOKUP(X23,Data!$B:$E,3,FALSE) -> #N/A | O23: TOTAL DE VENDAS - LINHA OFF ROAD | P23: A1100 | Q23: A1100.1 | R23: A1100.2 | S23: A1100.8 | T23: A1100.3 | U23: A1100.4 | V23: A1100.5 | W23: A1100.6 | X23: A1100.7
A24: =Translation!A53 -> LINHA 125 cc | B24: =Translation!$G$32 -> CONTA | C24: =Translation!$G$12 -> UNIDADES | D24: =Translation!$G$11 -> RECEITA (SEM IMPOSTOS) | E24: =Translation!$G$33 -> UNIDADES DEVOLVIDAS | F24: =Translation!$G$14 -> DEVOLUÇÃO DE VENDAS | G24: =Translation!$G$3 -> ABAT. E DESCONTO | H24: =Translation!$G$9 -> RECEITA LÍQUIDA | I24: =Translation!$G$2 -> CUSTO | J24: =Translation!$G$5 -> LUCRO BRUTO | O24: LINHA 125 cc | P24: =Translation!$G$32 -> CONTA | Q24: UNITS | R24: SALES | S24: URETURN | T24: SC | U24: DISC | V24: NS | W24: COS | X24: GP
A25: =Translation!A54 -> FACTOR YBR 125i ED | B25: A1110 | C25: =VLOOKUP(Q25,Data!$B:$E,3,FALSE) -> #N/A | D25: =VLOOKUP(R25,Data!$B:$E,3,FALSE) -> #N/A | E25: =VLOOKUP(S25,Data!$B:$E,3,FALSE) -> #N/A | F25: =VLOOKUP(T25,Data!$B:$E,3,FALSE) -> #N/A | G25: =VLOOKUP(U25,Data!$B:$E,3,FALSE) -> #N/A | H25: =VLOOKUP(V25,Data!$B:$E,3,FALSE) -> #N/A | I25: =VLOOKUP(W25,Data!$B:$E,3,FALSE) -> #N/A | J25: =VLOOKUP(X25,Data!$B:$E,3,FALSE) -> #N/A | O25: FACTOR YBR 125i ED | P25: A1110 | Q25: A1110.1 | R25: A1110.2 | S25: A1110.8 | T25: A1110.3 | U25: A1110.4 | V25: A1110.5 | W25: A1110.6 | X25: A1110.7
A26: FLUO ABS | B26: A1111 | C26: =VLOOKUP(Q26,Data!$B:$E,4,FALSE) -> #N/A | D26: =VLOOKUP(R26,Data!$B:$E,4,FALSE) -> #N/A | E26: =VLOOKUP(S26,Data!$B:$E,4,FALSE) -> #N/A | F26: =VLOOKUP(T26,Data!$B:$E,4,FALSE) -> #N/A | G26: =VLOOKUP(U26,Data!$B:$E,4,FALSE) -> #N/A | H26: =VLOOKUP(V26,Data!$B:$E,4,FALSE) -> #N/A | I26: =VLOOKUP(W26,Data!$B:$E,4,FALSE) -> #N/A | J26: =VLOOKUP(X26,Data!$B:$E,4,FALSE) -> #N/A | O26: FLUO ABS | P26: A1111 | Q26: A1111.1 | R26: A1111.2 | S26: A1111.8 | T26: A1111.3 | U26: A1111.4 | V26: A1111.5 | W26: A1111.6 | X26: A1111.7
A27: =Translation!A55 -> TOTAL DE VENDAS - LINHA 125 cc | B27: A1120 | C27: =VLOOKUP(Q27,Data!$B:$E,3,FALSE) -> #N/A | D27: =VLOOKUP(R27,Data!$B:$E,3,FALSE) -> #N/A | E27: =VLOOKUP(S27,Data!$B:$E,3,FALSE) -> #N/A | F27: =VLOOKUP(T27,Data!$B:$E,3,FALSE) -> #N/A | G27: =VLOOKUP(U27,Data!$B:$E,3,FALSE) -> #N/A | H27: =VLOOKUP(V27,Data!$B:$E,3,FALSE) -> #N/A | I27: =VLOOKUP(W27,Data!$B:$E,3,FALSE) -> #N/A | J27: =VLOOKUP(X27,Data!$B:$E,3,FALSE) -> #N/A | O27: TOTAL DE VENDAS - LINHA 125 cc | P27: A1120 | Q27: A1120.1 | R27: A1120.2 | S27: A1120.8 | T27: A1120.3 | U27: A1120.4 | V27: A1120.5 | W27: A1120.6 | X27: A1120.7
A28: =Translation!A56 -> LINHA 150 cc - Street | B28: =Translation!$G$32 -> CONTA | C28: =Translation!$G$12 -> UNIDADES | D28: =Translation!$G$11 -> RECEITA (SEM IMPOSTOS) | E28: =Translation!$G$33 -> UNIDADES DEVOLVIDAS | F28: =Translation!$G$14 -> DEVOLUÇÃO DE VENDAS | G28: =Translation!$G$3 -> ABAT. E DESCONTO | H28: =Translation!$G$9 -> RECEITA LÍQUIDA | I28: =Translation!$G$2 -> CUSTO | J28: =Translation!$G$5 -> LUCRO BRUTO | O28: LINHA 150 cc - Street | P28: =Translation!$G$32 -> CONTA | Q28: UNITS | R28: SALES | S28: URETURN | T28: SC | U28: DISC | V28: NS | W28: COS | X28: GP
A29: =Translation!A57 -> FACTOR 150E | B29: A1130 | C29: =VLOOKUP(Q29,Data!$B:$E,3,FALSE) -> #N/A | D29: =VLOOKUP(R29,Data!$B:$E,3,FALSE) -> #N/A | E29: =VLOOKUP(S29,Data!$B:$E,3,FALSE) -> #N/A | F29: =VLOOKUP(T29,Data!$B:$E,3,FALSE) -> #N/A | G29: =VLOOKUP(U29,Data!$B:$E,3,FALSE) -> #N/A | H29: =VLOOKUP(V29,Data!$B:$E,3,FALSE) -> #N/A | I29: =VLOOKUP(W29,Data!$B:$E,3,FALSE) -> #N/A | J29: =VLOOKUP(X29,Data!$B:$E,3,FALSE) -> #N/A | O29: FACTOR 150E | P29: A1130 | Q29: A1130.1 | R29: A1130.2 | S29: A1130.8 | T29: A1130.3 | U29: A1130.4 | V29: A1130.5 | W29: A1130.6 | X29: A1130.7
A30: =Translation!A58 -> FACTOR 150ED | B30: A1140 | C30: =VLOOKUP(Q30,Data!$B:$E,3,FALSE) -> #N/A | D30: =VLOOKUP(R30,Data!$B:$E,3,FALSE) -> #N/A | E30: =VLOOKUP(S30,Data!$B:$E,3,FALSE) -> #N/A | F30: =VLOOKUP(T30,Data!$B:$E,3,FALSE) -> #N/A | G30: =VLOOKUP(U30,Data!$B:$E,3,FALSE) -> #N/A | H30: =VLOOKUP(V30,Data!$B:$E,3,FALSE) -> #N/A | I30: =VLOOKUP(W30,Data!$B:$E,3,FALSE) -> #N/A | J30: =VLOOKUP(X30,Data!$B:$E,3,FALSE) -> #N/A | O30: FACTOR 150ED | P30: A1140 | Q30: A1140.1 | R30: A1140.2 | S30: A1140.8 | T30: A1140.3 | U30: A1140.4 | V30: A1140.5 | W30: A1140.6 | X30: A1140.7
A31: =Translation!A59 -> YS 150 FAZER SED | B31: A1150 | C31: =VLOOKUP(Q31,Data!$B:$E,3,FALSE) -> #N/A | D31: =VLOOKUP(R31,Data!$B:$E,3,FALSE) -> #N/A | E31: =VLOOKUP(S31,Data!$B:$E,3,FALSE) -> #N/A | F31: =VLOOKUP(T31,Data!$B:$E,3,FALSE) -> #N/A | G31: =VLOOKUP(U31,Data!$B:$E,3,FALSE) -> #N/A | H31: =VLOOKUP(V31,Data!$B:$E,3,FALSE) -> #N/A | I31: =VLOOKUP(W31,Data!$B:$E,3,FALSE) -> #N/A | J31: =VLOOKUP(X31,Data!$B:$E,3,FALSE) -> #N/A | O31: YS 150 FAZER SED | P31: A1150 | Q31: A1150.1 | R31: A1150.2 | S31: A1150.8 | T31: A1150.3 | U31: A1150.4 | V31: A1150.5 | W31: A1150.6 | X31: A1150.7
A32: YZF R15 ABS | B32: A1151 | C32: =VLOOKUP(Q32,Data!$B:$E,4,FALSE) -> #N/A | D32: =VLOOKUP(R32,Data!$B:$E,4,FALSE) -> #N/A | E32: =VLOOKUP(S32,Data!$B:$E,4,FALSE) -> #N/A | F32: =VLOOKUP(T32,Data!$B:$E,4,FALSE) -> #N/A | G32: =VLOOKUP(U32,Data!$B:$E,4,FALSE) -> #N/A | H32: =VLOOKUP(V32,Data!$B:$E,4,FALSE) -> #N/A | I32: =VLOOKUP(W32,Data!$B:$E,4,FALSE) -> #N/A | J32: =VLOOKUP(X32,Data!$B:$E,4,FALSE) -> #N/A | O32: YZF R15 ABS | P32: A1151 | Q32: A1151.1 | R32: A1151.2 | S32: A1151.8 | T32: A1151.3 | U32: A1151.4 | V32: A1151.5 | W32: A1151.6 | X32: A1151.7
A33: FZ15 FAZER ABS | B33: A1152 | C33: =VLOOKUP(Q33,Data!$B:$E,4,FALSE) -> #N/A | D33: =VLOOKUP(R33,Data!$B:$E,4,FALSE) -> #N/A | E33: =VLOOKUP(S33,Data!$B:$E,4,FALSE) -> #N/A | F33: =VLOOKUP(T33,Data!$B:$E,4,FALSE) -> #N/A | G33: =VLOOKUP(U33,Data!$B:$E,4,FALSE) -> #N/A | H33: =VLOOKUP(V33,Data!$B:$E,4,FALSE) -> #N/A | I33: =VLOOKUP(W33,Data!$B:$E,4,FALSE) -> #N/A | J33: =VLOOKUP(X33,Data!$B:$E,4,FALSE) -> #N/A | O33: FZ15 FAZER ABS | P33: A1152 | Q33: A1152.1 | R33: A1152.2 | S33: A1152.8 | T33: A1152.3 | U33: A1152.4 | V33: A1152.5 | W33: A1152.6 | X33: A1152.7
A34: =Translation!A60 -> LINHA 150 cc - On/Off | B34: =Translation!$G$32 -> CONTA | C34: =Translation!$G$12 -> UNIDADES | D34: =Translation!$G$11 -> RECEITA (SEM IMPOSTOS) | E34: =Translation!$G$33 -> UNIDADES DEVOLVIDAS | F34: =Translation!$G$14 -> DEVOLUÇÃO DE VENDAS | G34: =Translation!$G$3 -> ABAT. E DESCONTO | H34: =Translation!$G$9 -> RECEITA LÍQUIDA | I34: =Translation!$G$2 -> CUSTO | J34: =Translation!$G$5 -> LUCRO BRUTO | O34: LINHA 150 cc - On/Off | P34: =Translation!$G$32 -> CONTA | Q34: UNITS | R34: SALES | S34: URETURN | T34: SC | U34: DISC | V34: NS | W34: COS | X34: GP
A35: =Translation!A61 -> XTZ 150 CROSSER E | B35: A1160 | C35: =VLOOKUP(Q35,Data!$B:$E,3,FALSE) -> #N/A | D35: =VLOOKUP(R35,Data!$B:$E,3,FALSE) -> #N/A | E35: =VLOOKUP(S35,Data!$B:$E,3,FALSE) -> #N/A | F35: =VLOOKUP(T35,Data!$B:$E,3,FALSE) -> #N/A | G35: =VLOOKUP(U35,Data!$B:$E,3,FALSE) -> #N/A | H35: =VLOOKUP(V35,Data!$B:$E,3,FALSE) -> #N/A | I35: =VLOOKUP(W35,Data!$B:$E,3,FALSE) -> #N/A | J35: =VLOOKUP(X35,Data!$B:$E,3,FALSE) -> #N/A | O35: XTZ 150 CROSSER E | P35: A1160 | Q35: A1160.1 | R35: A1160.2 | S35: A1160.8 | T35: A1160.3 | U35: A1160.4 | V35: A1160.5 | W35: A1160.6 | X35: A1160.7
A36: =Translation!A62 -> XTZ 150 CROSSER ED | B36: A1170 | C36: =VLOOKUP(Q36,Data!$B:$E,3,FALSE) -> #N/A | D36: =VLOOKUP(R36,Data!$B:$E,3,FALSE) -> #N/A | E36: =VLOOKUP(S36,Data!$B:$E,3,FALSE) -> #N/A | F36: =VLOOKUP(T36,Data!$B:$E,3,FALSE) -> #N/A | G36: =VLOOKUP(U36,Data!$B:$E,3,FALSE) -> #N/A | H36: =VLOOKUP(V36,Data!$B:$E,3,FALSE) -> #N/A | I36: =VLOOKUP(W36,Data!$B:$E,3,FALSE) -> #N/A | J36: =VLOOKUP(X36,Data!$B:$E,3,FALSE) -> #N/A | O36: XTZ 150 CROSSER ED | P36: A1170 | Q36: A1170.1 | R36: A1170.2 | S36: A1170.8 | T36: A1170.3 | U36: A1170.4 | V36: A1170.5 | W36: A1170.6 | X36: A1170.7
A37: XTZ 150 CROSSER S | B37: A1174 | C37: =VLOOKUP(Q37,Data!$B:$E,3,FALSE) -> #N/A | D37: =VLOOKUP(R37,Data!$B:$E,3,FALSE) -> #N/A | E37: =VLOOKUP(S37,Data!$B:$E,3,FALSE) -> #N/A | F37: =VLOOKUP(T37,Data!$B:$E,3,FALSE) -> #N/A | G37: =VLOOKUP(U37,Data!$B:$E,3,FALSE) -> #N/A | H37: =VLOOKUP(V37,Data!$B:$E,3,FALSE) -> #N/A | I37: =VLOOKUP(W37,Data!$B:$E,3,FALSE) -> #N/A | J37: =VLOOKUP(X37,Data!$B:$E,3,FALSE) -> #N/A | O37: XTZ 150 CROSSER S | P37: A1174 | Q37: A1174.1 | R37: A1174.2 | S37: A1174.8 | T37: A1174.3 | U37: A1174.4 | V37: A1174.5 | W37: A1174.6 | X37: A1174.7
A38: XTZ 150 CROSSER Z | B38: A1176 | C38: =VLOOKUP(Q38,Data!$B:$E,3,FALSE) -> #N/A | D38: =VLOOKUP(R38,Data!$B:$E,3,FALSE) -> #N/A | E38: =VLOOKUP(S38,Data!$B:$E,3,FALSE) -> #N/A | F38: =VLOOKUP(T38,Data!$B:$E,3,FALSE) -> #N/A | G38: =VLOOKUP(U38,Data!$B:$E,3,FALSE) -> #N/A | H38: =VLOOKUP(V38,Data!$B:$E,3,FALSE) -> #N/A | I38: =VLOOKUP(W38,Data!$B:$E,3,FALSE) -> #N/A | J38: =VLOOKUP(X38,Data!$B:$E,3,FALSE) -> #N/A | O38: XTZ 150 CROSSER Z | P38: A1176 | Q38: A1176.1 | R38: A1176.2 | S38: A1176.8 | T38: A1176.3 | U38: A1176.4 | V38: A1176.5 | W38: A1176.6 | X38: A1176.7
A39: =Translation!A63 -> TOTAL DE VENDAS - LINHA 150 cc | B39: A1180 | C39: =VLOOKUP(Q39,Data!$B:$E,3,FALSE) -> #N/A | D39: =VLOOKUP(R39,Data!$B:$E,3,FALSE) -> #N/A | E39: =VLOOKUP(S39,Data!$B:$E,3,FALSE) -> #N/A | F39: =VLOOKUP(T39,Data!$B:$E,3,FALSE) -> #N/A | G39: =VLOOKUP(U39,Data!$B:$E,3,FALSE) -> #N/A | H39: =VLOOKUP(V39,Data!$B:$E,3,FALSE) -> #N/A | I39: =VLOOKUP(W39,Data!$B:$E,3,FALSE) -> #N/A | J39: =VLOOKUP(X39,Data!$B:$E,3,FALSE) -> #N/A | O39: TOTAL DE VENDAS - LINHA 150 cc | P39: A1180 | Q39: A1180.1 | R39: A1180.2 | S39: A1180.8 | T39: A1180.3 | U39: A1180.4 | V39: A1180.5 | W39: A1180.6 | X39: A1180.7
A40: =Translation!A64 -> LINHA 250 cc - Street | B40: =Translation!$G$32 -> CONTA | C40: =Translation!$G$12 -> UNIDADES | D40: =Translation!$G$11 -> RECEITA (SEM IMPOSTOS) | E40: =Translation!$G$33 -> UNIDADES DEVOLVIDAS | F40: =Translation!$G$14 -> DEVOLUÇÃO DE VENDAS | G40: =Translation!$G$3 -> ABAT. E DESCONTO | H40: =Translation!$G$9 -> RECEITA LÍQUIDA | I40: =Translation!$G$2 -> CUSTO | J40: =Translation!$G$5 -> LUCRO BRUTO | O40: LINHA 250 cc - Street | P40: =Translation!$G$32 -> CONTA | Q40: UNITS | R40: SALES | S40: URETURN | T40: SC | U40: DISC | V40: NS | W40: COS | X40: GP
...

Sheet Data
C1: Dealer Name | D1: Nippon Motos - Bragança | E1: Nippon Motos - Bragança | G1: LanguageID | H1: 1 | I1: =IF(G2=1,J1,K1) -> Jan | J1: Jan | K1: Jan | N1: 1 | O1: BAC | P1: 8 | Q1: CITY_NM
C2: Location | H2: 2 | I2: =IF(G3=1,J2,K2) -> Fev | J2: Feb | K2: Fev | N2: 2 | O2: End Month | P2: 9 | Q2: POSTL_STATE_CD
C3: City | D3: BRAGANCA PAULISTA | H3: 3 | I3: =IF(G4=1,J3,K3) -> Mar | J3: Mar | K3: Mar | N3: 3 | O3: End Year | P3: 10 | Q3: POSTL_CD
C4: BAC | D4: 1696-01 | E4: 1696-01 | H4: 4 | I4: =IF(G5=1,J4,K4) -> Abr | J4: Apr | K4: Abr | N4: 4 | O4: Dealer Name | P4: 11 | Q4: GMBA_ACTVTN_DT
C5: State | H5: 5 | I5: =IF(G6=1,J5,K5) -> Mai | J5: May | K5: Mai | N5: 5 | O5: ADDR_LINE_1_TXT | P5: 15 | Q5: Dealer'
C6: End Month / End Year | D6: 4 | E6: 2026 | H6: 6 | I6: =IF(G7=1,J6,K6) -> Jun | J6: Jun | K6: Jun | N6: 6 | O6: ADDR_LINE_2_TXT | P6: 16 | Q6: CountryCode
C7: Dealer/Composite | D7: Dealer | H7: 7 | I7: =IF(G8=1,J7,K7) -> Jul | J7: Jul | K7: Jul | P7: 17 | Q7: Location
C8: Country Code | H8: 8 | I8: =IF(G9=1,J8,K8) -> Ago | J8: Aug | K8: Ago | P8: 18 | Q8: @PhaseID
C9: Submission Status | H9: 9 | I9: =IF(G10=1,J9,K9) -> Set | J9: Sep | K9: Set
C10: Reserved | H10: 10 | I10: =IF(G11=1,J10,K10) -> Out | J10: Oct | K10: Out
H11: 11 | I11: =IF(G12=1,J11,K11) -> Nov | J11: Nov | K11: Nov
H12: 12 | I12: =IF(G13=1,J12,K12) -> Dez | J12: Dec | K12: Dez
A13: System Assigned # | B13: Local Acct # | C13: Description | D13: Month Data | E13: YTD Data
A14: 1 | B14: A1000.1 | C14: NEO 125 - UNIDADES | D14: 0 | E14: 0
A15: 2 | B15: A1000.2 | C15: NEO 125 - RECEITA | D15: 0 | E15: 0
A16: 3 | B16: A1000.3 | C16: NEO 125 - DEVOLUÇÃO DE VENDAS | D16: 0 | E16: 0
A17: 4 | B17: A1000.4 | C17: NEO 125 - ABAT. E DESCONTO | D17: 0 | E17: 0
A18: 5 | B18: A1000.5 | C18: NEO 125 - VENDA LÍQUIDA | D18: 0 | E18: 0
A19: 6 | B19: A1000.6 | C19: NEO 125 - CUSTO | D19: 0 | E19: 0
A20: 7 | B20: A1000.7 | C20: NEO 125 - LUCRO BRUTO | D20: 0 | E20: 0
A21: 8 | B21: A1010.1 | C21: NMAX 160 ABS - UNIDADES | D21: 0 | E21: 0
A22: 9 | B22: A1010.2 | C22: NMAX 160 ABS - RECEITA | D22: 0 | E22: 0
A23: 10 | B23: A1010.3 | C23: NMAX 160 ABS - DEVOLUÇÃO DE VENDAS | D23: 0 | E23: 0
A24: 11 | B24: A1010.4 | C24: NMAX 160 ABS - ABAT. E DESCONTO | D24: 0 | E24: 0
A25: 12 | B25: A1010.5 | C25: NMAX 160 ABS - VENDA LÍQUIDA | D25: 0 | E25: 0
... A1434: 10005 | B1434: DLRMTHS | C1434: Dealer Report Period | D1434: 1 | E1434: 4

Sheet Translation
A1: =IF(LanguageID=1,B1,C1) -> VENDA DE NOVOS | B1: New Sales | C1: VENDA DE NOVOS | F1: =Translation!$G$1 -> VALOR | G1: =IF(LanguageID=1,H1,I1) -> VALOR | H1: AMOUNT | I1: VALOR
A2: =IF(LanguageID=1,B2,C2) -> VENDAS DE USADOS | B2: Used Sales | C2: VENDAS DE USADOS | F2: COS | G2: =IF(LanguageID=1,H2,I2) -> CUSTO | H2: COST OF SALES | I2: CUSTO
A3: =IF(LanguageID=1,B3,C3) -> PEÇAS E ACESSÓRIOS | B3: Parts | C3: PEÇAS E ACESSÓRIOS | F3: DISC | G3: =IF(LanguageID=1,H3,I3) -> ABAT. E DESCONTO | H3: DISCOUNT | I3: ABAT. E DESCONTO
A4: =IF(LanguageID=1,B4,C4) -> SERVIÇO | B4: Service | C4: SERVIÇO | F4: DP | G4: =IF(LanguageID=1,H4,I4) -> DIRECT PROFIT | H4: DIRECT PROFIT | I4: DIRECT PROFIT
A5: =IF(LanguageID=1,B5,C5) -> F & I | B5: F & I | C5: F & I | F5: GP | G5: =IF(LanguageID=1,H5,I5) -> LUCRO BRUTO | H5: GROSS PROFIT | I5: LUCRO BRUTO
A6: =IF(LanguageID=1,B6,C6) -> ADMIN | B6: Admin | C6: ADMIN | F6: HC | G6: =IF(LanguageID=1,H6,I6) -> NUN. FUNCIONÁRIOS | H6: HEADCOUNT | I6: NUN. FUNCIONÁRIOS
A7: =IF(LanguageID=1,B7,C7) -> BALANÇO | B7: Balance Sheet | C7: BALANÇO | F7: HOURS | G7: =IF(LanguageID=1,H7,I7) -> HORAS | H7: HOURS | I7: HORAS
F8: JC | G8: =IF(LanguageID=1,H8,I8) -> O.S. | H8: JOB CARDS | I8: O.S.
F9: NS | G9: =IF(LanguageID=1,H9,I9) -> RECEITA LÍQUIDA | H9: NET SALES | I9: RECEITA LÍQUIDA
F10: RR | G10: =IF(LanguageID=1,H10,I10) -> TARIFA REAL | H10: RECOVERY RATE | I10: TARIFA REAL
F11: SALES | G11: =IF(LanguageID=1,H11,I11) -> RECEITA (SEM IMPOSTOS) | H11: SALES | I11: RECEITA (SEM IMPOSTOS)
F12: UNITS | G12: =IF(LanguageID=1,H12,I12) -> UNIDADES | H12: UNITS | I12: UNIDADES
F13: VALUE | G13: =IF(LanguageID=1,H13,I13) -> VALOR | H13: VALUE | I13: VALOR
F14: SC | G14: =IF(LanguageID=1,H14,I14) -> DEVOLUÇÃO DE VENDAS | H14: SALE CANCELED | I14: DEVOLUÇÃO DE VENDAS
F15: AREA | G15: =IF(LanguageID=1,H15,I15) -> ÁREA | H15: AREA | I15: ÁREA
F16: NNEW | G16: =IF(LanguageID=1,H16,I16) -> NOVOS | H16: NEW | I16: NOVOS
F17: NUSED | G17: =IF(LanguageID=1,H17,I17) -> USADOS | H17: USED | I17: USADOS
B18: EN | C18: PT | F18: NF&I | G18: =IF(LanguageID=1,H18,I18) -> F & I | H18: F & I | I18: F & I
A19: =IF(LanguageID=1,B19,C19) -> Localização: | B19: Location: | C19: Localização: | F19: NPARTS | G19: =IF(LanguageID=1,H19,I19) -> PEÇAS E ACESS. | H19: PARTS | I19: PEÇAS E ACESS.
A20: =IF(LanguageID=1,B20,C20) -> Concessionário: | B20: =IF(Data!D7="Composite", "Composite: ", "Dealer: ") -> Dealer: | C20: =IF(Data!D7="Composite", "Comparativo: ", "Concessionário: ") -> Concessionário: | F20: NSERV | G20: =IF(LanguageID=1,H20,I20) -> SERVIÇO | H20: SERVICES | I20: SERVIÇO
A21: =IF(LanguageID=1,B21,C21) -> Período: | B21: Report Period Ending: | C21: Período: | F21: NADM | G21: =IF(LanguageID=1,H21,I21) -> ADM | H21: ADMIN | I21: ADM
A22: =IF(LanguageID=1,B22,C22) -> DRE YAMAHA BMI - Acumulado | B22: YAMAHA BMI Financial Statement - YTD | C22: DRE YAMAHA BMI - Acumulado | F22: NTOT | G22: =IF(LanguageID=1,H22,I22) -> TOTAL | H22: TOTAL | I22: TOTAL
A23: =IF(LanguageID=1,B23,C23) -> DRE YAMAHA BMI - Mês | B23: YAMAHA BMI Financial Statement - MTH | C23: DRE YAMAHA BMI - Mês | F23: ANEW | G23: =IF(LanguageID=1,H23,I23) -> NOVOS | H23: NEW | I23: NOVOS
F24: AUSED | G24: =IF(LanguageID=1,H24,I24) -> USADOS | H24: USED | I24: USADOS
F25: AF&I | G25: =IF(LanguageID=1,H25,I25) -> F & I | H25: F & I | I25: F & I
F26: APARTS | G26: =IF(LanguageID=1,H26,I26) -> PEÇAS E ACESS. | H26: PARTS | I26: PEÇAS E ACESS.
F27: ASERV | G27: =IF(LanguageID=1,H27,I27) -> SERVIÇO | H27: SERVICES | I27: SERVIÇO
F28: AADM | G28: =IF(LanguageID=1,H28,I28) -> ADM | H28: ADMIN | I28: ADM
F29: ATOT | G29: =IF(LanguageID=1,H29,I29) -> TOTAL | H29: TOTAL | I29: TOTAL
F30: =Translation!$G$30 -> ESTOQUE FINAL | G30: =IF(LanguageID=1,H30,I30) -> ESTOQUE FINAL | H30: FINAL STOCK | I30: ESTOQUE FINAL
F31: SHARE | G31: =IF(LanguageID=1,H31,I31) -> % | H31: EQUITY INTEREST (%) | I31: %
F32: =Translation!$G$32 -> CONTA | G32: =IF(LanguageID=1,H32,I32) -> CONTA | H32: ACCT | I32: CONTA
F33: URETURN | G33: UNIDADES DEVOLVIDAS | H33: RETURNED UNITS | I33: UNIDADES DEVOLVIDAS
A35: =IF(LanguageID=1,B35,C35) -> LINHA SCOOTER <200 cc | B35: LINE SCOOTER <200 cc | C35: LINHA SCOOTER <200 cc
A36: =IF(LanguageID=1,B36,C36) -> NEO 125 | B36: NEO 125 | C36: NEO 125
A37: =IF(LanguageID=1,B37,C37) -> NMAX 160 ABS | B37: NMAX 160 ABS | C37: NMAX 160 ABS
A38: =IF(LanguageID=1,B38,C38) -> LINHA SCOOTER >200 cc | B38: LINE SCOOTER >200 cc | C38: LINHA SCOOTER >200 cc
A39: =IF(LanguageID=1,B39,C39) -> TMAX 530 | B39: TMAX 530 | C39: TMAX 530
A40: =IF(LanguageID=1,B40,C40) -> TOTAL DE VENDAS - SCOOTER | B40: TOTAL SALES - SCOOTER | C40: TOTAL DE VENDAS - SCOOTER
A41: =IF(LanguageID=1,B41,C41) -> LINHA OFF ROAD | B41: LINE OFF ROAD | C41: LINHA OFF ROAD
...
